Workbook

Sheet README
B2: Vistra (NYSE: VST) — Initiation model
B4: Accompanies the coverage initiation of October 3, 2026 (bpleon.com/vst-initiation-2026-10-03). HOLD, 12-18 month price target $140.
B5: Priced at the September 30, 2026 close of $138.35. Ten-year unlevered DCF (Q4 2026 stub + 2027-2035), mid-year convention,
B6: terminal value = 50% x 9.0x 2035E EBITDA + 50% Gordon growth at 2.5%. WACC 8.70%. Three scenarios, probability-weighted.
B8: Tabs: Assumptions (every input, color-keyed) · Scenarios (EBITDA paths) · DCF (all three cases + weighting) · Reverse DCF
B9: (what the Street's $218 requires) · Comps (IPP peers + the four lenses and target weighting) · 3-Statement (condensed build)
B10: · Sensitivity (WACC x exit multiple).
B12: Inputs are shaded cream; formulas flow from them. Change an input and the target rebuilds.
B13: Sourcing: company filings and releases (T1), named data providers (T2); desk assumptions marked [A] on the Assumptions tab.
B14: Released October 26, 2026, incorporating the October 20 corrections to the note (rating, target and estimates unchanged).
B15: Disclosure: the author holds a long position in Vistra (25 shares, bought September 30, 2026, before publication of the note
B16: — see the dated correction on the note). Research and opinion, not investment advice. (c) 2026 Brandon Leon / bpleon.com.

Sheet Assumptions
B2: Assumptions — every input to the model
B3: Shaded cells are inputs. [A] = desk assumption; everything else is sourced in the note's footnotes.
B5: WACC build (note fn 12)
B6: Risk-free rate (10-yr UST, 9/29/26) | C6: 0.0526 | E6: US Treasury
B7: Beta (peers unlevered, relevered at VST pro forma) | C7: 1.32 | E7: desk calc
B8: Equity risk premium (Damodaran implied, 9/1/26) | C8: 0.0414
B9: Pre-tax cost of debt | C9: 0.062 | E9: [A] recent issuance + curve
B10: Tax rate for WACC / statutory | C10: 0.21
B11: Cost of hybrids (preferred/juniors) | C11: 0.071 | E11: [A] blended coupon
B12: Weight: equity | C12: 0.64
B13: Weight: debt | C13: 0.33
B14: Weight: hybrids | C14: 0.03
B15: Cost of equity | C15: =C6+C7*C8 -> 0.107248
B16: WACC | C16: =C12*C15+C13*C9*(1-C10)+C14*C11 -> 0.08693212
B18: Terminal value & convention
B19: Exit multiple on 2035E EBITDA | C19: 9
B20: Perpetual growth (Gordon) | C20: 0.025
B21: Exit / Gordon blend weight on exit | C21: 0.5
B22: Horizon end discount period (years) | C22: 9.25 | E22: Q4'26 stub + 9 full years
B24: Equity bridge ($M, 6/30/26 pro forma; note fn 12)
B25: Funded debt | C25: 19895 | E25: 10-Q: LTD incl current 19,595 + A/R financing 300
B26: Preferred stock (liquidation) | C26: 2476
B27: Vistra Vision forward repurchase obligation | C27: 613
B28: Cogentrix cash + assumed debt | C28: 3800 | E28: 2.3B cash + 1.5B assumed
B29: Less: cash | C29: -435
B30: Less: acquired tax benefits | C30: -700
B31: Bridge total ($M) | C31: =SUM(C25:C30) -> 25649
B32: Shares outstanding, pro forma (M) | C32: 340.6 | E32: 335.6M (10-Q cover) + 5.0M Cogentrix
B33: Reference price (9/30/26 close) | C33: 138.35
B35: Operating assumptions ($B unless noted)
B36: D&A, 2026 | C36: 1.85 | E36: [A]
B37: D&A growth | C37: 0.02 | E37: [A]
B38: Capex (incl nuclear fuel), 2026 | C38: 2 | E38: [A] vs H1'26 actual 1.572
B39: Capex growth | C39: 0.02 | E39: [A]
B40: Cash tax rate 2026 | C40: 0.04 | E40: loss carryforwards
B41: Cash tax rate 2027 | C41: 0.1
B42: Cash tax rate 2028 | C42: 0.15
B43: Cash tax rate 2029 on (statutory) | C43: 0.21
B45: Scenario EBITDA anchors ($B) and probabilities
C46: 2026 | D46: 2027 | E46: 2028 | F46: 2030 | G46: post-2030 growth | H46: probability
...

Sheet Scenarios
B2: Adjusted EBITDA paths, 2026-2035 ($B)
C4: 2026 | D4: 2027 | E4: 2028 | F4: 2029 | G4: 2030 | H4: 2031 | I4: 2032 | J4: 2033 | K4: 2034 | L4: 2035
B5: Pessimistic | C5: =Assumptions!C47 -> 7.2 | D5: =Assumptions!D47 -> 7.67 | E5: =Assumptions!E47 -> 7.23 | F5: =SQRT(E5*G5) -> 7.063073 | G5: =Assumptions!F47 -> 6.9 | H5: =G5*(1+Assumptions!G47) -> 7.010676 | I5: =H5*(1+Assumptions!G47) -> 7.1231272 | J5: =I5*(1+Assumptions!G47) -> 7.2373822 | K5: =J5*(1+Assumptions!G47) -> 7.3534698 | L5: =K5*(1+Assumptions!G47) -> 7.4714195
B6: Base | C6: =Assumptions!C48 -> 7.2 | D6: =Assumptions!D48 -> 8.04 | E6: =Assumptions!E48 -> 8.19 | F6: =SQRT(E6*G6) -> 8.3924966 | G6: =Assumptions!F48 -> 8.6 | H6: =G6*(1+Assumptions!G48) -> 8.770796 | I6: =H6*(1+Assumptions!G48) -> 8.944984 | J6: =I6*(1+Assumptions!G48) -> 9.1226314 | K6: =J6*(1+Assumptions!G48) -> 9.3038069 | L6: =K6*(1+Assumptions!G48) -> 9.4885805
B7: Optimistic | C7: =Assumptions!C49 -> 7.2 | D7: =Assumptions!D49 -> 8.29 | E7: =Assumptions!E49 -> 8.87 | F7: =SQRT(E7*G7) -> 9.1795969 | G7: =Assumptions!F49 -> 9.5 | H7: =G7*(1+Assumptions!G49) -> 9.715745 | I7: =H7*(1+Assumptions!G49) -> 9.9363896 | J7: =I7*(1+Assumptions!G49) -> 10.162045 | K7: =J7*(1+Assumptions!G49) -> 10.392825 | L7: =K7*(1+Assumptions!G49) -> 10.628846
B9: Consensus check | C9: =Assumptions!C52 -> 7.23 | D9: =Assumptions!C53 -> 8.05 | E9: =Assumptions!C54 -> 8.79 | F9: =F6*($E$9/$E$6) -> 9.0073316 | G9: =G6*($E$9/$E$6) -> 9.2300366 | H9: =H6*($E$9/$E$6) -> 9.4133452 | I9: =I6*($E$9/$E$6) -> 9.6002942 | J9: =J6*($E$9/$E$6) -> 9.790956 | K9: =K6*($E$9/$E$6) -> 9.9854044 | L9: =L6*($E$9/$E$6) -> 10.183715
B11: Common cost structure ($B)
B12: D&A | C12: =Assumptions!C36 -> 1.85 | D12: =C12*(1+Assumptions!$C$37) -> 1.887 | E12: =D12*(1+Assumptions!$C$37) -> 1.92474 | F12: =E12*(1+Assumptions!$C$37) -> 1.9632348 | G12: =F12*(1+Assumptions!$C$37) -> 2.0024995 | H12: =G12*(1+Assumptions!$C$37) -> 2.0425495 | I12: =H12*(1+Assumptions!$C$37) -> 2.0834005 | J12: =I12*(1+Assumptions!$C$37) -> 2.1250685 | K12: =J12*(1+Assumptions!$C$37) -> 2.1675699 | L12: =K12*(1+Assumptions!$C$37) -> 2.2109213
B13: Capex incl nuclear fuel | C13: =Assumptions!C38 -> 2 | D13: =C13*(1+Assumptions!$C$39) -> 2.04 | E13: =D13*(1+Assumptions!$C$39) -> 2.0808 | F13: =E13*(1+Assumptions!$C$39) -> 2.122416 | G13: =F13*(1+Assumptions!$C$39) -> 2.1648643 | H13: =G13*(1+Assumptions!$C$39) -> 2.2081616 | I13: =H13*(1+Assumptions!$C$39) -> 2.2523248 | J13: =I13*(1+Assumptions!$C$39) -> 2.2973713 | K13: =J13*(1+Assumptions!$C$39) -> 2.3433188 | L13: =K13*(1+Assumptions!$C$39) -> 2.3901851
B14: Cash tax rate | C14: =Assumptions!C40 -> 0.04 | D14: =Assumptions!C41 -> 0.1 | E14: =Assumptions!C42 -> 0.15 | F14: =Assumptions!C43 -> 0.21 | G14: =Assumptions!C43 -> 0.21 | H14: =Assumptions!C43 -> 0.21 | I14: =Assumptions!C43 -> 0.21 | J14: =Assumptions!C43 -> 0.21 | K14: =Assumptions!C43 -> 0.21 | L14: =Assumptions!C43 -> 0.21
B16: Scenario definitions — Pessimistic: the Texas curve is right, PJM capacity normalizes after 2029. Base: no Texas deal beyond AWS, PJM flat after the cap. Optimistic: a second Texas hyperscaler deal, ERCOT recovers.

Sheet DCF
B2: Ten-year unlevered DCF — Q4 2026 stub + 2027-2035, mid-year convention
B3: FCFF = EBITDA − cash taxes on EBIT − capex. TV = blend of exit multiple and Gordon. All $B except per-share.
B5: Pessimistic (25%)
C6: Q4'26 | D6: 2027 | E6: 2028 | F6: 2029 | G6: 2030 | H6: 2031 | I6: 2032 | J6: 2033 | K6: 2034 | L6: 2035
B7: EBITDA | C7: =0.25*Scenarios!C5 -> 1.8 | D7: =Scenarios!D5 -> 7.67 | E7: =Scenarios!E5 -> 7.23 | F7: =Scenarios!F5 -> 7.063073 | G7: =Scenarios!G5 -> 6.9 | H7: =Scenarios!H5 -> 7.010676 | I7: =Scenarios!I5 -> 7.1231272 | J7: =Scenarios!J5 -> 7.2373822 | K7: =Scenarios!K5 -> 7.3534698 | L7: =Scenarios!L5 -> 7.4714195
B8: Less: cash taxes | C8: =-0.25*Scenarios!C14*(Scenarios!C5-Scenarios!C12) -> -0.0535 | D8: =-Scenarios!D14*(Scenarios!D5-Scenarios!D12) -> -0.5783 | E8: =-Scenarios!E14*(Scenarios!E5-Scenarios!E12) -> -0.795789 | F8: =-Scenarios!F14*(Scenarios!F5-Scenarios!F12) -> -1.070966 | G8: =-Scenarios!G14*(Scenarios!G5-Scenarios!G12) -> -1.0284751 | H8: =-Scenarios!H14*(Scenarios!H5-Scenarios!H12) -> -1.0433066 | I8: =-Scenarios!I14*(Scenarios!I5-Scenarios!I12) -> -1.0583426 | J8: =-Scenarios!J14*(Scenarios!J5-Scenarios!J12) -> -1.0735859 | K8: =-Scenarios!K14*(Scenarios!K5-Scenarios!K12) -> -1.089039 | L8: =-Scenarios!L14*(Scenarios!L5-Scenarios!L12) -> -1.1047046
B9: Less: capex | C9: =-0.25*Scenarios!C13 -> -0.5 | D9: =-Scenarios!D13 -> -2.04 | E9: =-Scenarios!E13 -> -2.0808 | F9: =-Scenarios!F13 -> -2.122416 | G9: =-Scenarios!G13 -> -2.1648643 | H9: =-Scenarios!H13 -> -2.2081616 | I9: =-Scenarios!I13 -> -2.2523248 | J9: =-Scenarios!J13 -> -2.2973713 | K9: =-Scenarios!K13 -> -2.3433188 | L9: =-Scenarios!L13 -> -2.3901851
B10: FCFF | C10: =SUM(C7:C9) -> 1.2465 | D10: =SUM(D7:D9) -> 5.0517 | E10: =SUM(E7:E9) -> 4.353411 | F10: =SUM(F7:F9) -> 3.869691 | G10: =SUM(G7:G9) -> 3.7066606 | H10: =SUM(H7:H9) -> 3.7592078 | I10: =SUM(I7:I9) -> 3.8124598 | J10: =SUM(J7:J9) -> 3.866425 | ... L10: =SUM(L7:L9) -> 3.9765297
B11: Discount period (mid-year) | C11: 0.125 | D11: 0.75 | E11: 1.75 | F11: 2.75 | G11: 3.75 | H11: 4.75 | I11: 5.75 | J11: 6.75 | K11: 7.75 | L11: 8.75
B12: PV of FCFF | C12: =C10/(1+Assumptions!$C$16)^C11 -> 1.233579 | D12: =D10/(1+Assumptions!$C$16)^D11 -> 4.7455411 | E12: =E10/(1+Assumptions!$C$16)^E11 -> 3.7624907 | F12: =F10/(1+Assumptions!$C$16)^F11 -> 3.0769442 | G12: =G10/(1+Assumptions!$C$16)^G11 -> 2.7115882 | H12: =H10/(1+Assumptions!$C$16)^H11 -> 2.5300833 | I12: =I10/(1+Assumptions!$C$16)^I11 -> 2.3607029 | J12: =J10/(1+Assumptions!$C$16)^J11 -> 2.2026385 | ... L12: =L10/(1+Assumptions!$C$16)^L11 -> 1.9174897
B13: Sum PV, explicit period | C13: =SUM(C12:L12) -> 26.596193
B14: TV: exit component (9.0x 2035E EBITDA) | C14: =Assumptions!C19*L7 -> 67.242775
B15: TV: Gordon component | C15: =L10*(1+Assumptions!C20)/(Assumptions!C16-Assumptions!C20) -> 65.81307
B16: Terminal value (blend) | C16: =Assumptions!C21*C14+(1-Assumptions!C21)*C15 -> 66.527923
B17: PV of terminal value | C17: =C16/(1+Assumptions!$C$16)^Assumptions!$C$22 -> 30.770287
B18: Enterprise value | C18: =C13+C17 -> 57.366481 | D18: TV share of EV: | E18: =C17/C18 -> 0.53638095
B19: Less: bridge ($B) | C19: =-Assumptions!C31/1000 -> -25.649
B20: Equity value ($B) | C20: =C18+C19 -> 31.717481
B21: Per share ($) | C21: =C20*1000/Assumptions!C32 -> 93.122374
B22: Base (50%)
C23: Q4'26 | D23: 2027 | E23: 2028 | F23: 2029 | G23: 2030 | H23: 2031 | I23: 2032 | J23: 2033 | K23: 2034 | L23: 2035
B24: EBITDA | C24: =0.25*Scenarios!C6 -> 1.8 | D24: =Scenarios!D6 -> 8.04 | E24: =Scenarios!E6 -> 8.19 | F24: =Scenarios!F6 -> 8.3924966 | G24: =Scenarios!G6 -> 8.6 | H24: =Scenarios!H6 -> 8.770796 | I24: =Scenarios!I6 -> 8.944984 | J24: =Scenarios!J6 -> 9.1226314 | K24: =Scenarios!K6 -> 9.3038069 | L24: =Scenarios!L6 -> 9.4885805
B25: Less: cash taxes | C25: =-0.25*Scenarios!C14*(Scenarios!C6-Scenarios!C12) -> -0.0535 | D25: =-Scenarios!D14*(Scenarios!D6-Scenarios!D12) -> -0.6153 | E25: =-Scenarios!E14*(Scenarios!E6-Scenarios!E12) -> -0.939789 | F25: =-Scenarios!F14*(Scenarios!F6-Scenarios!F12) -> -1.350145 | G25: =-Scenarios!G14*(Scenarios!G6-Scenarios!G12) -> -1.3854751 | H25: =-Scenarios!H14*(Scenarios!H6-Scenarios!H12) -> -1.4129318 | I25: =-Scenarios!I14*(Scenarios!I6-Scenarios!I12) -> -1.4409325 | J25: =-Scenarios!J14*(Scenarios!J6-Scenarios!J12) -> -1.4694882 | K25: =-Scenarios!K14*(Scenarios!K6-Scenarios!K12) -> -1.4986098 | L25: =-Scenarios!L14*(Scenarios!L6-Scenarios!L12) -> -1.5283084
B26: Less: capex | C26: =-0.25*Scenarios!C13 -> -0.5 | D26: =-Scenarios!D13 -> -2.04 | E26: =-Scenarios!E13 -> -2.0808 | F26: =-Scenarios!F13 -> -2.122416 | G26: =-Scenarios!G13 -> -2.1648643 | H26: =-Scenarios!H13 -> -2.2081616 | I26: =-Scenarios!I13 -> -2.2523248 | J26: =-Scenarios!J13 -> -2.2973713 | K26: =-Scenarios!K13 -> -2.3433188 | L26: =-Scenarios!L13 -> -2.3901851
B27: FCFF | C27: =SUM(C24:C26) -> 1.2465 | D27: =SUM(D24:D26) -> 5.3847 | E27: =SUM(E24:E26) -> 5.169411 | F27: =SUM(F24:F26) -> 4.9199357 | G27: =SUM(G24:G26) -> 5.0496606 | H27: =SUM(H24:H26) -> 5.1497026 | I27: =SUM(I24:I26) -> 5.2517266 | J27: =SUM(J24:J26) -> 5.3557718 | ... L27: =SUM(L24:L26) -> 5.5700869
B28: Discount period (mid-year) | C28: 0.125 | D28: 0.75 | E28: 1.75 | F28: 2.75 | G28: 3.75 | H28: 4.75 | I28: 5.75 | J28: 6.75 | K28: 7.75 | L28: 8.75
B29: PV of FCFF | C29: =C27/(1+Assumptions!$C$16)^C28 -> 1.233579 | D29: =D27/(1+Assumptions!$C$16)^D28 -> 5.0583595 | E29: =E27/(1+Assumptions!$C$16)^E28 -> 4.467729 | F29: =F27/(1+Assumptions!$C$16)^F28 -> 3.9120353 | G29: =G27/(1+Assumptions!$C$16)^G28 -> 3.6940528 | H29: =H27/(1+Assumptions!$C$16)^H28 -> 3.4659368 | I29: =I27/(1+Assumptions!$C$16)^I28 -> 3.2519075 | J29: =J27/(1+Assumptions!$C$16)^J28 -> 3.0510949 | ... L29: =L27/(1+Assumptions!$C$16)^L28 -> 2.6859058
B30: Sum PV, explicit period | C30: =SUM(C29:L29) -> 33.683284
B31: TV: exit component (9.0x 2035E EBITDA) | C31: =Assumptions!C19*L24 -> 85.397224
B32: TV: Gordon component | C32: =L27*(1+Assumptions!C20)/(Assumptions!C16-Assumptions!C20) -> 92.187044
B33: Terminal value (blend) | C33: =Assumptions!C21*C31+(1-Assumptions!C21)*C32 -> 88.792134
B34: PV of terminal value | C34: =C33/(1+Assumptions!$C$16)^Assumptions!$C$22 -> 41.067861
B35: Enterprise value | C35: =C30+C34 -> 74.751144 | D35: TV share of EV: | E35: =C34/C35 -> 0.54939441
B36: Less: bridge ($B) | C36: =-Assumptions!C31/1000 -> -25.649
B37: Equity value ($B) | C37: =C35+C36 -> 49.102144
B38: Per share ($) | C38: =C37*1000/Assumptions!C32 -> 144.16367
B39: Optimistic (25%)
C40: Q4'26 | D40: 2027 | E40: 2028 | F40: 2029 | G40: 2030 | H40: 2031 | I40: 2032 | J40: 2033 | K40: 2034 | L40: 2035
B41: EBITDA | C41: =0.25*Scenarios!C7 -> 1.8 | D41: =Scenarios!D7 -> 8.29 | E41: =Scenarios!E7 -> 8.87 | F41: =Scenarios!F7 -> 9.1795969 | G41: =Scenarios!G7 -> 9.5 | H41: =Scenarios!H7 -> 9.715745 | I41: =Scenarios!I7 -> 9.9363896 | J41: =Scenarios!J7 -> 10.162045 | K41: =Scenarios!K7 -> 10.392825 | L41: =Scenarios!L7 -> 10.628846
B42: Less: cash taxes | C42: =-0.25*Scenarios!C14*(Scenarios!C7-Scenarios!C12) -> -0.0535 | D42: =-Scenarios!D14*(Scenarios!D7-Scenarios!D12) -> -0.6403 | E42: =-Scenarios!E14*(Scenarios!E7-Scenarios!E12) -> -1.041789 | F42: =-Scenarios!F14*(Scenarios!F7-Scenarios!F12) -> -1.515436 | G42: =-Scenarios!G14*(Scenarios!G7-Scenarios!G12) -> -1.5744751 | H42: =-Scenarios!H14*(Scenarios!H7-Scenarios!H12) -> -1.6113711 | I42: =-Scenarios!I14*(Scenarios!I7-Scenarios!I12) -> -1.6491277 | J42: =-Scenarios!J14*(Scenarios!J7-Scenarios!J12) -> -1.6877651 | K42: =-Scenarios!K14*(Scenarios!K7-Scenarios!K12) -> -1.7273036 | L42: =-Scenarios!L14*(Scenarios!L7-Scenarios!L12) -> -1.7677642
...

Sheet Reverse DCF
B2: Reverse DCF — what the Street's $218 mean target requires
B4: Hold the base-case cash flows fixed and solve for the market's implied inputs.
B6: Exit-multiple route (terminal value = 100% exit multiple, WACC 8.70%)
B7: 2035 exit multiple required for $218 | C7: 15.1
B8: value at that multiple (check) | C8: =((SUM(DCF!C29:L29))+(C7*DCF!L24)/(1+Assumptions!C16)^Assumptions!C22-Assumptions!C31/1000)*1000/Assumptions!C32 -> 218.15201
B10: Discount-rate route (blended terminal value as in the primary DCF)
B11: WACC required for $218 | C11: 0.0653
B12: implied cost of equity at VST's weights | C12: =(C11-Assumptions!C13*Assumptions!C9*(1-Assumptions!C10)-Assumptions!C14*Assumptions!C11)/Assumptions!C12 -> 0.073447812
B14: Reading
B15: At 8.70%, $218 needs a 15.1x multiple on a 2035 fleet of gas and aging nuclear plants - a regulated-utility multiple.
B16: At a 9.0x exit, $218 needs roughly a 6.5% WACC - a cost of equity under 7.5% for a beta-1.3 stock over a 5.3% Treasury.
B17: Re-run on consensus EBITDA (7.23/8.05/8.79 for 2026-28) the DCF gives about $161-162: $17 above our base case and $57
B18: below the Street mean. The disagreement is the rate, not the earnings. (The exit-multiple sensitivity here uses an
B19: exit-only terminal value; the primary DCF blends exit and Gordon - the distinction the note's Oct 20 note formalized.)

Sheet Comps
B2: Peer comparison and the four lenses
B4: EV / 2027E EBITDA (as of September 30; VST pro forma for Cogentrix)
B5: Company | C5: EV/2027E EBITDA | E5: Note
B6: NRG | C6: 7.2 | E6: down 42% in a year
B7: Talen (TLN) | C7: 8.9
B8: Vistra (VST, pro forma) | C8: 9.2 | E8: our 2027E EBITDA
B9: PSEG (PEG) | C9: 10.9
B10: Dominion (D) | C10: 11.4
B11: Constellation (CEG) | C11: 12.1 | E11: nuclear premium
B13: IPP peers used for the lens: CEG, TLN, NRG (listed independent power producers)
B16: IPP average | D16: =AVERAGE(C6,C7,C11) -> 9.4
B18: The four lenses (weights on Assumptions)
B19: Lens | C19: Value | D19: Weight
B20: 1 - DCF, probability-weighted | C20: =DCF!C75 -> 138.66037 | D20: =Assumptions!C64 -> 0.5
B21: 2 - EV / 2027E EBITDA at the IPP average | C21: =(D16*Assumptions!D48-Assumptions!C31/1000)*1000/Assumptions!C32 -> 146.58544 | D21: =Assumptions!C65 -> 0.25
B22: 3 - FCF yield at 7.0% (2027E, after growth capex & preferred) | C22: =Assumptions!C59/Assumptions!C58*1000/Assumptions!C32 -> 138.99841 | D22: =Assumptions!C66 -> 0.25
B23: 4 - P/E at the 14.5x peer median (cross-check, unweighted) | C23: =Assumptions!C60*Assumptions!C61 -> 145.23174 | D23: -
B25: Weighted fair value | C25: =C20*D20+C21*D21+C22*D22 -> 140.72614
B26: Price target (rounded) | C26: =ROUND(C25/5,0)*5 -> 140
B27: vs reference price (9/30 close $138.35) | C27: =C26/Assumptions!C33-1 -> 0.011926274

Sheet Statements
B2: Condensed statements build ($B except per share) - base case
B3: Full revenue history is deliberately omitted: for integrated generation + retail, revenue is hedge and pass-through noise (note, section 1). EBITDA is the anchor.
C5: 2026E | D5: 2027E | E5: 2028E
B6: Income statement
B7: Revenue (consensus, reference only) | C7: 22.46 | D7: 23.91 | E7: n/a
B8: Ongoing Ops Adjusted EBITDA | C8: =Scenarios!C6 -> 7.2 | D8: =Scenarios!D6 -> 8.04 | E8: =Scenarios!E6 -> 8.19
B9: D&A | C9: =-Scenarios!C12 -> -1.85 | D9: =-Scenarios!D12 -> -1.887 | E9: =-Scenarios!E12 -> -1.92474
B10: EBIT | C10: =C8+C9 -> 5.35 | D10: =D8+D9 -> 6.153 | E10: =E8+E9 -> 6.26526
B11: Interest expense, net [A] | C11: -1.45 | D11: -1.65 | E11: -1.68
B12: Pre-tax income | C12: =C10+C11 -> 3.9 | D12: =D10+D11 -> 4.503 | E12: =E10+E11 -> 4.58526
B13: Taxes (21% book rate) | C13: =-0.21*C12 -> -0.819 | D13: =-0.21*D12 -> -0.94563 | E13: =-0.21*E12 -> -0.9629046
B14: Net income | C14: =C12+C13 -> 3.081 | D14: =D12+D13 -> 3.55737 | E14: =E12+E13 -> 3.6223554
B15: Preferred dividends | C15: -0.192 | D15: -0.192 | E15: -0.192
B16: Net to common | C16: =C14+C15 -> 2.889 | D16: =D14+D15 -> 3.36537 | E16: =E14+E15 -> 3.4303554
B18: Shares (M), avg [A: buybacks ~5M/yr] | C18: 340.6 | D18: 336 | E18: 331
B20: Consensus EPS (stockanalysis.com) | C20: 8.62 | D20: 10.37 | E20: 11.91
B24: EPS, desk ($) | C24: =C16*1000/C18 -> 8.4820904 | D24: =D16*1000/D18 -> 10.015982 | E24: =E16*1000/E18 -> 10.363611
B26: Cash flow build
B27: Adj. FCF before growth (guide / desk) | C27: 4.33 | D27: 4.55 | E27: 4.4
B28: FCFbG per share ($) | C28: =C27*1000/C18 -> 12.71286 | D28: =D27*1000/D18 -> 13.541667 | E28: =E27*1000/E18 -> 13.293051
B29: FCFbG yield on $138.35 | C29: =C28/Assumptions!C33 -> 0.091889119 | D29: =D28/Assumptions!C33 -> 0.097879774 | E29: =E28/Assumptions!C33 -> 0.096082771
B30: Less: growth capex [A] | C30: -0.95 | D30: -1.044 | E30: -1
B31: Less: preferred dividends | C31: =C15 -> -0.192 | D31: =D15 -> -0.192 | E31: =E15 -> -0.192
B32: FCF after growth & preferred | C32: =C27+C30+C31 -> 3.188 | D32: =D27+D30+D31 -> 3.314 | E32: =E27+E30+E31 -> 3.208
B34: Balance sheet summary (6/30/26, 10-Q)
B35: Cash | C35: 0.435
B36: Total funded debt (incl A/R financing) | C36: 19.895
B37: Forward repurchase obligation (Vision) | C37: 0.613
B38: Net debt | C38: 20.073
B39: Preferred (liquidation) | C39: 2.476
B40: Net debt / FY26 guide-mid EBITDA | C40: 2.8x
B41: Management deleveraging path | C41: ~2.3x by YE2027
B42: Liquidity | C42: 6.295

Sheet Sensitivity
B2: Base-case value per share - WACC x exit multiple (blended TV as in the primary DCF)
B4: exit \ WACC | C4: 0.075 | D4: 0.08 | E4: 0.085 | F4: 0.087 | G4: 0.09 | H4: 0.095 | I4: 0.1
B5: 7 | C5: =((DCF!C27/(1+C$4)^0.125+DCF!D27/(1+C$4)^0.75+DCF!E27/(1+C$4)^1.75+DCF!F27/(1+C$4)^2.75+DCF!G27/(1+C$4)^3.75+DCF!H27/(1+C$4)^4.75+DCF!I27/(1+C$4)^5.75+DCF!J27/(1+C$4)^6.75+DCF!K27/(1+C$4)^7.75+DCF!L27/(1+C$4)^8.75)+(Assumptions!$C$21*$B5*DCF!L24+(1-Assumptions!$C$21)*DCF!L27*(1+Assumptions!$C$20)/(C$4-Assumptions!$C$20))/(1+C$4)^Assumptions!$C$22-Assumptions!$C$31/1000)*1000/Assumptions!$C$32 -> 164.01189 | D5: =((DCF!C27/(1+D$4)^0.125+DCF!D27/(1+D$4)^0.75+DCF!E27/(1+D$4)^1.75+DCF!F27/(1+D$4)^2.75+DCF!G27/(1+D$4)^3.75+DCF!H27/(1+D$4)^4.75+DCF!I27/(1+D$4)^5.75+DCF!J27/(1+D$4)^6.75+DCF!K27/(1+D$4)^7.75+DCF!L27/(1+D$4)^8.75)+(Assumptions!$C$21*$B5*DCF!L24+(1-Assumptions!$C$21)*DCF!L27*(1+Assumptions!$C$20)/(D$4-Assumptions!$C$20))/(1+D$4)^Assumptions!$C$22-Assumptions!$C$31/1000)*1000/Assumptions!$C$32 -> 148.85223 | E5: =((DCF!C27/(1+E$4)^0.125+DCF!D27/(1+E$4)^0.75+DCF!E27/(1+E$4)^1.75+DCF!F27/(1+E$4)^2.75+DCF!G27/(1+E$4)^3.75+DCF!H27/(1+E$4)^4.75+DCF!I27/(1+E$4)^5.75+DCF!J27/(1+E$4)^6.75+DCF!K27/(1+E$4)^7.75+DCF!L27/(1+E$4)^8.75)+(Assumptions!$C$21*$B5*DCF!L24+(1-Assumptions!$C$21)*DCF!L27*(1+Assumptions!$C$20)/(E$4-Assumptions!$C$20))/(1+E$4)^Assumptions!$C$22-Assumptions!$C$31/1000)*1000/Assumptions!$C$32 -> 135.83834 | F5: =((DCF!C27/(1+F$4)^0.125+DCF!D27/(1+F$4)^0.75+DCF!E27/(1+F$4)^1.75+DCF!F27/(1+F$4)^2.75+DCF!G27/(1+F$4)^3.75+DCF!H27/(1+F$4)^4.75+DCF!I27/(1+F$4)^5.75+DCF!J27/(1+F$4)^6.75+DCF!K27/(1+F$4)^7.75+DCF!L27/(1+F$4)^8.75)+(Assumptions!$C$21*$B5*DCF!L24+(1-Assumptions!$C$21)*DCF!L27*(1+Assumptions!$C$20)/(F$4-Assumptions!$C$20))/(1+F$4)^Assumptions!$C$22-Assumptions!$C$31/1000)*1000/Assumptions!$C$32 -> 131.12273 | G5: =((DCF!C27/(1+G$4)^0.125+DCF!D27/(1+G$4)^0.75+DCF!E27/(1+G$4)^1.75+DCF!F27/(1+G$4)^2.75+DCF!G27/(1+G$4)^3.75+DCF!H27/(1+G$4)^4.75+DCF!I27/(1+G$4)^5.75+DCF!J27/(1+G$4)^6.75+DCF!K27/(1+G$4)^7.75+DCF!L27/(1+G$4)^8.75)+(Assumptions!$C$21*$B5*DCF!L24+(1-Assumptions!$C$21)*DCF!L27*(1+Assumptions!$C$20)/(G$4-Assumptions!$C$20))/(1+G$4)^Assumptions!$C$22-Assumptions!$C$31/1000)*1000/Assumptions!$C$32 -> 124.49787 | H5: =((DCF!C27/(1+H$4)^0.125+DCF!D27/(1+H$4)^0.75+DCF!E27/(1+H$4)^1.75+DCF!F27/(1+H$4)^2.75+DCF!G27/(1+H$4)^3.75+DCF!H27/(1+H$4)^4.75+DCF!I27/(1+H$4)^5.75+DCF!J27/(1+H$4)^6.75+DCF!K27/(1+H$4)^7.75+DCF!L27/(1+H$4)^8.75)+(Assumptions!$C$21*$B5*DCF!L24+(1-Assumptions!$C$21)*DCF!L27*(1+Assumptions!$C$20)/(H$4-Assumptions!$C$20))/(1+H$4)^Assumptions!$C$22-Assumptions!$C$31/1000)*1000/Assumptions!$C$32 -> 114.49202 | I5: =((DCF!C27/(1+I$4)^0.125+DCF!D27/(1+I$4)^0.75+DCF!E27/(1+I$4)^1.75+DCF!F27/(1+I$4)^2.75+DCF!G27/(1+I$4)^3.75+DCF!H27/(1+I$4)^4.75+DCF!I27/(1+I$4)^5.75+DCF!J27/(1+I$4)^6.75+DCF!K27/(1+I$4)^7.75+DCF!L27/(1+I$4)^8.75)+(Assumptions!$C$21*$B5*DCF!L24+(1-Assumptions!$C$21)*DCF!L27*(1+Assumptions!$C$20)/(I$4-Assumptions!$C$20))/(1+I$4)^Assumptions!$C$22-Assumptions!$C$31/1000)*1000/Assumptions!$C$32 -> 105.57118
B6: 8 | C6: =((DCF!C27/(1+C$4)^0.125+DCF!D27/(1+C$4)^0.75+DCF!E27/(1+C$4)^1.75+DCF!F27/(1+C$4)^2.75+DCF!G27/(1+C$4)^3.75+DCF!H27/(1+C$4)^4.75+DCF!I27/(1+C$4)^5.75+DCF!J27/(1+C$4)^6.75+DCF!K27/(1+C$4)^7.75+DCF!L27/(1+C$4)^8.75)+(Assumptions!$C$21*$B6*DCF!L24+(1-Assumptions!$C$21)*DCF!L27*(1+Assumptions!$C$20)/(C$4-Assumptions!$C$20))/(1+C$4)^Assumptions!$C$22-Assumptions!$C$31/1000)*1000/Assumptions!$C$32 -> 171.14696 | D6: =((DCF!C27/(1+D$4)^0.125+DCF!D27/(1+D$4)^0.75+DCF!E27/(1+D$4)^1.75+DCF!F27/(1+D$4)^2.75+DCF!G27/(1+D$4)^3.75+DCF!H27/(1+D$4)^4.75+DCF!I27/(1+D$4)^5.75+DCF!J27/(1+D$4)^6.75+DCF!K27/(1+D$4)^7.75+DCF!L27/(1+D$4)^8.75)+(Assumptions!$C$21*$B6*DCF!L24+(1-Assumptions!$C$21)*DCF!L27*(1+Assumptions!$C$20)/(D$4-Assumptions!$C$20))/(1+D$4)^Assumptions!$C$22-Assumptions!$C$31/1000)*1000/Assumptions!$C$32 -> 155.68752 | E6: =((DCF!C27/(1+E$4)^0.125+DCF!D27/(1+E$4)^0.75+DCF!E27/(1+E$4)^1.75+DCF!F27/(1+E$4)^2.75+DCF!G27/(1+E$4)^3.75+DCF!H27/(1+E$4)^4.75+DCF!I27/(1+E$4)^5.75+DCF!J27/(1+E$4)^6.75+DCF!K27/(1+E$4)^7.75+DCF!L27/(1+E$4)^8.75)+(Assumptions!$C$21*$B6*DCF!L24+(1-Assumptions!$C$21)*DCF!L27*(1+Assumptions!$C$20)/(E$4-Assumptions!$C$20))/(1+E$4)^Assumptions!$C$22-Assumptions!$C$31/1000)*1000/Assumptions!$C$32 -> 142.38774 | F6: =((DCF!C27/(1+F$4)^0.125+DCF!D27/(1+F$4)^0.75+DCF!E27/(1+F$4)^1.75+DCF!F27/(1+F$4)^2.75+DCF!G27/(1+F$4)^3.75+DCF!H27/(1+F$4)^4.75+DCF!I27/(1+F$4)^5.75+DCF!J27/(1+F$4)^6.75+DCF!K27/(1+F$4)^7.75+DCF!L27/(1+F$4)^8.75)+(Assumptions!$C$21*$B6*DCF!L24+(1-Assumptions!$C$21)*DCF!L27*(1+Assumptions!$C$20)/(F$4-Assumptions!$C$20))/(1+F$4)^Assumptions!$C$22-Assumptions!$C$31/1000)*1000/Assumptions!$C$32 -> 137.5615 | G6: =((DCF!C27/(1+G$4)^0.125+DCF!D27/(1+G$4)^0.75+DCF!E27/(1+G$4)^1.75+DCF!F27/(1+G$4)^2.75+DCF!G27/(1+G$4)^3.75+DCF!H27/(1+G$4)^4.75+DCF!I27/(1+G$4)^5.75+DCF!J27/(1+G$4)^6.75+DCF!K27/(1+G$4)^7.75+DCF!L27/(1+G$4)^8.75)+(Assumptions!$C$21*$B6*DCF!L24+(1-Assumptions!$C$21)*DCF!L27*(1+Assumptions!$C$20)/(G$4-Assumptions!$C$20))/(1+G$4)^Assumptions!$C$22-Assumptions!$C$31/1000)*1000/Assumptions!$C$32 -> 130.77457 | H6: =((DCF!C27/(1+H$4)^0.125+DCF!D27/(1+H$4)^0.75+DCF!E27/(1+H$4)^1.75+DCF!F27/(1+H$4)^2.75+DCF!G27/(1+H$4)^3.75+DCF!H27/(1+H$4)^4.75+DCF!I27/(1+H$4)^5.75+DCF!J27/(1+H$4)^6.75+DCF!K27/(1+H$4)^7.75+DCF!L27/(1+H$4)^8.75)+(Assumptions!$C$21*$B6*DCF!L24+(1-Assumptions!$C$21)*DCF!L27*(1+Assumptions!$C$20)/(H$4-Assumptions!$C$20))/(1+H$4)^Assumptions!$C$22-Assumptions!$C$31/1000)*1000/Assumptions!$C$32 -> 120.50855 | I6: =((DCF!C27/(1+I$4)^0.125+DCF!D27/(1+I$4)^0.75+DCF!E27/(1+I$4)^1.75+DCF!F27/(1+I$4)^2.75+DCF!G27/(1+I$4)^3.75+DCF!H27/(1+I$4)^4.75+DCF!I27/(1+I$4)^5.75+DCF!J27/(1+I$4)^6.75+DCF!K27/(1+I$4)^7.75+DCF!L27/(1+I$4)^8.75)+(Assumptions!$C$21*$B6*DCF!L24+(1-Assumptions!$C$21)*DCF!L27*(1+Assumptions!$C$20)/(I$4-Assumptions!$C$20))/(1+I$4)^Assumptions!$C$22-Assumptions!$C$31/1000)*1000/Assumptions!$C$32 -> 111.33943
B7: 9 | C7: =((DCF!C27/(1+C$4)^0.125+DCF!D27/(1+C$4)^0.75+DCF!E27/(1+C$4)^1.75+DCF!F27/(1+C$4)^2.75+DCF!G27/(1+C$4)^3.75+DCF!H27/(1+C$4)^4.75+DCF!I27/(1+C$4)^5.75+DCF!J27/(1+C$4)^6.75+DCF!K27/(1+C$4)^7.75+DCF!L27/(1+C$4)^8.75)+(Assumptions!$C$21*$B7*DCF!L24+(1-Assumptions!$C$21)*DCF!L27*(1+Assumptions!$C$20)/(C$4-Assumptions!$C$20))/(1+C$4)^Assumptions!$C$22-Assumptions!$C$31/1000)*1000/Assumptions!$C$32 -> 178.28203 | D7: =((DCF!C27/(1+D$4)^0.125+DCF!D27/(1+D$4)^0.75+DCF!E27/(1+D$4)^1.75+DCF!F27/(1+D$4)^2.75+DCF!G27/(1+D$4)^3.75+DCF!H27/(1+D$4)^4.75+DCF!I27/(1+D$4)^5.75+DCF!J27/(1+D$4)^6.75+DCF!K27/(1+D$4)^7.75+DCF!L27/(1+D$4)^8.75)+(Assumptions!$C$21*$B7*DCF!L24+(1-Assumptions!$C$21)*DCF!L27*(1+Assumptions!$C$20)/(D$4-Assumptions!$C$20))/(1+D$4)^Assumptions!$C$22-Assumptions!$C$31/1000)*1000/Assumptions!$C$32 -> 162.52281 | E7: =((DCF!C27/(1+E$4)^0.125+DCF!D27/(1+E$4)^0.75+DCF!E27/(1+E$4)^1.75+DCF!F27/(1+E$4)^2.75+DCF!G27/(1+E$4)^3.75+DCF!H27/(1+E$4)^4.75+DCF!I27/(1+E$4)^5.75+DCF!J27/(1+E$4)^6.75+DCF!K27/(1+E$4)^7.75+DCF!L27/(1+E$4)^8.75)+(Assumptions!$C$21*$B7*DCF!L24+(1-Assumptions!$C$21)*DCF!L27*(1+Assumptions!$C$20)/(E$4-Assumptions!$C$20))/(1+E$4)^Assumptions!$C$22-Assumptions!$C$31/1000)*1000/Assumptions!$C$32 -> 148.93714 | F7: =((DCF!C27/(1+F$4)^0.125+DCF!D27/(1+F$4)^0.75+DCF!E27/(1+F$4)^1.75+DCF!F27/(1+F$4)^2.75+DCF!G27/(1+F$4)^3.75+DCF!H27/(1+F$4)^4.75+DCF!I27/(1+F$4)^5.75+DCF!J27/(1+F$4)^6.75+DCF!K27/(1+F$4)^7.75+DCF!L27/(1+F$4)^8.75)+(Assumptions!$C$21*$B7*DCF!L24+(1-Assumptions!$C$21)*DCF!L27*(1+Assumptions!$C$20)/(F$4-Assumptions!$C$20))/(1+F$4)^Assumptions!$C$22-Assumptions!$C$31/1000)*1000/Assumptions!$C$32 -> 144.00028 | G7: =((DCF!C27/(1+G$4)^0.125+DCF!D27/(1+G$4)^0.75+DCF!E27/(1+G$4)^1.75+DCF!F27/(1+G$4)^2.75+DCF!G27/(1+G$4)^3.75+DCF!H27/(1+G$4)^4.75+DCF!I27/(1+G$4)^5.75+DCF!J27/(1+G$4)^6.75+DCF!K27/(1+G$4)^7.75+DCF!L27/(1+G$4)^8.75)+(Assumptions!$C$21*$B7*DCF!L24+(1-Assumptions!$C$21)*DCF!L27*(1+Assumptions!$C$20)/(G$4-Assumptions!$C$20))/(1+G$4)^Assumptions!$C$22-Assumptions!$C$31/1000)*1000/Assumptions!$C$32 -> 137.05127 | H7: =((DCF!C27/(1+H$4)^0.125+DCF!D27/(1+H$4)^0.75+DCF!E27/(1+H$4)^1.75+DCF!F27/(1+H$4)^2.75+DCF!G27/(1+H$4)^3.75+DCF!H27/(1+H$4)^4.75+DCF!I27/(1+H$4)^5.75+DCF!J27/(1+H$4)^6.75+DCF!K27/(1+H$4)^7.75+DCF!L27/(1+H$4)^8.75)+(Assumptions!$C$21*$B7*DCF!L24+(1-Assumptions!$C$21)*DCF!L27*(1+Assumptions!$C$20)/(H$4-Assumptions!$C$20))/(1+H$4)^Assumptions!$C$22-Assumptions!$C$31/1000)*1000/Assumptions!$C$32 -> 126.52508 | I7: =((DCF!C27/(1+I$4)^0.125+DCF!D27/(1+I$4)^0.75+DCF!E27/(1+I$4)^1.75+DCF!F27/(1+I$4)^2.75+DCF!G27/(1+I$4)^3.75+DCF!H27/(1+I$4)^4.75+DCF!I27/(1+I$4)^5.75+DCF!J27/(1+I$4)^6.75+DCF!K27/(1+I$4)^7.75+DCF!L27/(1+I$4)^8.75)+(Assumptions!$C$21*$B7*DCF!L24+(1-Assumptions!$C$21)*DCF!L27*(1+Assumptions!$C$20)/(I$4-Assumptions!$C$20))/(1+I$4)^Assumptions!$C$22-Assumptions!$C$31/1000)*1000/Assumptions!$C$32 -> 117.10769
B8: 10 | C8: =((DCF!C27/(1+C$4)^0.125+DCF!D27/(1+C$4)^0.75+DCF!E27/(1+C$4)^1.75+DCF!F27/(1+C$4)^2.75+DCF!G27/(1+C$4)^3.75+DCF!H27/(1+C$4)^4.75+DCF!I27/(1+C$4)^5.75+DCF!J27/(1+C$4)^6.75+DCF!K27/(1+C$4)^7.75+DCF!L27/(1+C$4)^8.75)+(Assumptions!$C$21*$B8*DCF!L24+(1-Assumptions!$C$21)*DCF!L27*(1+Assumptions!$C$20)/(C$4-Assumptions!$C$20))/(1+C$4)^Assumptions!$C$22-Assumptions!$C$31/1000)*1000/Assumptions!$C$32 -> 185.4171 | D8: =((DCF!C27/(1+D$4)^0.125+DCF!D27/(1+D$4)^0.75+DCF!E27/(1+D$4)^1.75+DCF!F27/(1+D$4)^2.75+DCF!G27/(1+D$4)^3.75+DCF!H27/(1+D$4)^4.75+DCF!I27/(1+D$4)^5.75+DCF!J27/(1+D$4)^6.75+DCF!K27/(1+D$4)^7.75+DCF!L27/(1+D$4)^8.75)+(Assumptions!$C$21*$B8*DCF!L24+(1-Assumptions!$C$21)*DCF!L27*(1+Assumptions!$C$20)/(D$4-Assumptions!$C$20))/(1+D$4)^Assumptions!$C$22-Assumptions!$C$31/1000)*1000/Assumptions!$C$32 -> 169.3581 | E8: =((DCF!C27/(1+E$4)^0.125+DCF!D27/(1+E$4)^0.75+DCF!E27/(1+E$4)^1.75+DCF!F27/(1+E$4)^2.75+DCF!G27/(1+E$4)^3.75+DCF!H27/(1+E$4)^4.75+DCF!I27/(1+E$4)^5.75+DCF!J27/(1+E$4)^6.75+DCF!K27/(1+E$4)^7.75+DCF!L27/(1+E$4)^8.75)+(Assumptions!$C$21*$B8*DCF!L24+(1-Assumptions!$C$21)*DCF!L27*(1+Assumptions!$C$20)/(E$4-Assumptions!$C$20))/(1+E$4)^Assumptions!$C$22-Assumptions!$C$31/1000)*1000/Assumptions!$C$32 -> 155.48654 | F8: =((DCF!C27/(1+F$4)^0.125+DCF!D27/(1+F$4)^0.75+DCF!E27/(1+F$4)^1.75+DCF!F27/(1+F$4)^2.75+DCF!G27/(1+F$4)^3.75+DCF!H27/(1+F$4)^4.75+DCF!I27/(1+F$4)^5.75+DCF!J27/(1+F$4)^6.75+DCF!K27/(1+F$4)^7.75+DCF!L27/(1+F$4)^8.75)+(Assumptions!$C$21*$B8*DCF!L24+(1-Assumptions!$C$21)*DCF!L27*(1+Assumptions!$C$20)/(F$4-Assumptions!$C$20))/(1+F$4)^Assumptions!$C$22-Assumptions!$C$31/1000)*1000/Assumptions!$C$32 -> 150.43906 | G8: =((DCF!C27/(1+G$4)^0.125+DCF!D27/(1+G$4)^0.75+DCF!E27/(1+G$4)^1.75+DCF!F27/(1+G$4)^2.75+DCF!G27/(1+G$4)^3.75+DCF!H27/(1+G$4)^4.75+DCF!I27/(1+G$4)^5.75+DCF!J27/(1+G$4)^6.75+DCF!K27/(1+G$4)^7.75+DCF!L27/(1+G$4)^8.75)+(Assumptions!$C$21*$B8*DCF!L24+(1-Assumptions!$C$21)*DCF!L27*(1+Assumptions!$C$20)/(G$4-Assumptions!$C$20))/(1+G$4)^Assumptions!$C$22-Assumptions!$C$31/1000)*1000/Assumptions!$C$32 -> 143.32797 | H8: =((DCF!C27/(1+H$4)^0.125+DCF!D27/(1+H$4)^0.75+DCF!E27/(1+H$4)^1.75+DCF!F27/(1+H$4)^2.75+DCF!G27/(1+H$4)^3.75+DCF!H27/(1+H$4)^4.75+DCF!I27/(1+H$4)^5.75+DCF!J27/(1+H$4)^6.75+DCF!K27/(1+H$4)^7.75+DCF!L27/(1+H$4)^8.75)+(Assumptions!$C$21*$B8*DCF!L24+(1-Assumptions!$C$21)*DCF!L27*(1+Assumptions!$C$20)/(H$4-Assumptions!$C$20))/(1+H$4)^Assumptions!$C$22-Assumptions!$C$31/1000)*1000/Assumptions!$C$32 -> 132.54161 | I8: =((DCF!C27/(1+I$4)^0.125+DCF!D27/(1+I$4)^0.75+DCF!E27/(1+I$4)^1.75+DCF!F27/(1+I$4)^2.75+DCF!G27/(1+I$4)^3.75+DCF!H27/(1+I$4)^4.75+DCF!I27/(1+I$4)^5.75+DCF!J27/(1+I$4)^6.75+DCF!K27/(1+I$4)^7.75+DCF!L27/(1+I$4)^8.75)+(Assumptions!$C$21*$B8*DCF!L24+(1-Assumptions!$C$21)*DCF!L27*(1+Assumptions!$C$20)/(I$4-Assumptions!$C$20))/(1+I$4)^Assumptions!$C$22-Assumptions!$C$31/1000)*1000/Assumptions!$C$32 -> 122.87594
B9: 11 | C9: =((DCF!C27/(1+C$4)^0.125+DCF!D27/(1+C$4)^0.75+DCF!E27/(1+C$4)^1.75+DCF!F27/(1+C$4)^2.75+DCF!G27/(1+C$4)^3.75+DCF!H27/(1+C$4)^4.75+DCF!I27/(1+C$4)^5.75+DCF!J27/(1+C$4)^6.75+DCF!K27/(1+C$4)^7.75+DCF!L27/(1+C$4)^8.75)+(Assumptions!$C$21*$B9*DCF!L24+(1-Assumptions!$C$21)*DCF!L27*(1+Assumptions!$C$20)/(C$4-Assumptions!$C$20))/(1+C$4)^Assumptions!$C$22-Assumptions!$C$31/1000)*1000/Assumptions!$C$32 -> 192.55217 | D9: =((DCF!C27/(1+D$4)^0.125+DCF!D27/(1+D$4)^0.75+DCF!E27/(1+D$4)^1.75+DCF!F27/(1+D$4)^2.75+DCF!G27/(1+D$4)^3.75+DCF!H27/(1+D$4)^4.75+DCF!I27/(1+D$4)^5.75+DCF!J27/(1+D$4)^6.75+DCF!K27/(1+D$4)^7.75+DCF!L27/(1+D$4)^8.75)+(Assumptions!$C$21*$B9*DCF!L24+(1-Assumptions!$C$21)*DCF!L27*(1+Assumptions!$C$20)/(D$4-Assumptions!$C$20))/(1+D$4)^Assumptions!$C$22-Assumptions!$C$31/1000)*1000/Assumptions!$C$32 -> 176.19339 | E9: =((DCF!C27/(1+E$4)^0.125+DCF!D27/(1+E$4)^0.75+DCF!E27/(1+E$4)^1.75+DCF!F27/(1+E$4)^2.75+DCF!G27/(1+E$4)^3.75+DCF!H27/(1+E$4)^4.75+DCF!I27/(1+E$4)^5.75+DCF!J27/(1+E$4)^6.75+DCF!K27/(1+E$4)^7.75+DCF!L27/(1+E$4)^8.75)+(Assumptions!$C$21*$B9*DCF!L24+(1-Assumptions!$C$21)*DCF!L27*(1+Assumptions!$C$20)/(E$4-Assumptions!$C$20))/(1+E$4)^Assumptions!$C$22-Assumptions!$C$31/1000)*1000/Assumptions!$C$32 -> 162.03594 | F9: =((DCF!C27/(1+F$4)^0.125+DCF!D27/(1+F$4)^0.75+DCF!E27/(1+F$4)^1.75+DCF!F27/(1+F$4)^2.75+DCF!G27/(1+F$4)^3.75+DCF!H27/(1+F$4)^4.75+DCF!I27/(1+F$4)^5.75+DCF!J27/(1+F$4)^6.75+DCF!K27/(1+F$4)^7.75+DCF!L27/(1+F$4)^8.75)+(Assumptions!$C$21*$B9*DCF!L24+(1-Assumptions!$C$21)*DCF!L27*(1+Assumptions!$C$20)/(F$4-Assumptions!$C$20))/(1+F$4)^Assumptions!$C$22-Assumptions!$C$31/1000)*1000/Assumptions!$C$32 -> 156.87783 | G9: =((DCF!C27/(1+G$4)^0.125+DCF!D27/(1+G$4)^0.75+DCF!E27/(1+G$4)^1.75+DCF!F27/(1+G$4)^2.75+DCF!G27/(1+G$4)^3.75+DCF!H27/(1+G$4)^4.75+DCF!I27/(1+G$4)^5.75+DCF!J27/(1+G$4)^6.75+DCF!K27/(1+G$4)^7.75+DCF!L27/(1+G$4)^8.75)+(Assumptions!$C$21*$B9*DCF!L24+(1-Assumptions!$C$21)*DCF!L27*(1+Assumptions!$C$20)/(G$4-Assumptions!$C$20))/(1+G$4)^Assumptions!$C$22-Assumptions!$C$31/1000)*1000/Assumptions!$C$32 -> 149.60467 | H9: =((DCF!C27/(1+H$4)^0.125+DCF!D27/(1+H$4)^0.75+DCF!E27/(1+H$4)^1.75+DCF!F27/(1+H$4)^2.75+DCF!G27/(1+H$4)^3.75+DCF!H27/(1+H$4)^4.75+DCF!I27/(1+H$4)^5.75+DCF!J27/(1+H$4)^6.75+DCF!K27/(1+H$4)^7.75+DCF!L27/(1+H$4)^8.75)+(Assumptions!$C$21*$B9*DCF!L24+(1-Assumptions!$C$21)*DCF!L27*(1+Assumptions!$C$20)/(H$4-Assumptions!$C$20))/(1+H$4)^Assumptions!$C$22-Assumptions!$C$31/1000)*1000/Assumptions!$C$32 -> 138.55814 | I9: =((DCF!C27/(1+I$4)^0.125+DCF!D27/(1+I$4)^0.75+DCF!E27/(1+I$4)^1.75+DCF!F27/(1+I$4)^2.75+DCF!G27/(1+I$4)^3.75+DCF!H27/(1+I$4)^4.75+DCF!I27/(1+I$4)^5.75+DCF!J27/(1+I$4)^6.75+DCF!K27/(1+I$4)^7.75+DCF!L27/(1+I$4)^8.75)+(Assumptions!$C$21*$B9*DCF!L24+(1-Assumptions!$C$21)*DCF!L27*(1+Assumptions!$C$20)/(I$4-Assumptions!$C$20))/(1+I$4)^Assumptions!$C$22-Assumptions!$C$31/1000)*1000/Assumptions!$C$32 -> 128.64419
B11: Each 50bp of WACC is worth roughly $11-13 a share near the base case; the grid steepens as WACC approaches the 2.5% Gordon growth rate.
