Workbook
Name ib_betaT: Drivers!$B$26
Name ib_cxpct: Drivers!$B$18
Name ib_dapct: Drivers!$B$17
Name ib_EBDA1: Forecast!$C$5
Name ib_EBDA2: Forecast!$D$5
Name ib_EBDA3: Forecast!$E$5
Name ib_EBDA4: Forecast!$F$5
Name ib_EBDA5: Forecast!$G$5
Name ib_ebmgn: Drivers!$B$16
Name ib_entrym: Drivers!$B$35
Name ib_erp: Drivers!$B$24
Name ib_exitm: Drivers!$B$32
Name ib_FCF1: Forecast!$C$13
Name ib_FCF2: Forecast!$D$13
Name ib_FCF3: Forecast!$E$13
Name ib_FCF4: Forecast!$F$13
Name ib_FCF5: Forecast!$G$13
Name ib_grw1: Drivers!$B$11
Name ib_grw2: Drivers!$B$12
Name ib_grw3: Drivers!$B$13
Name ib_grw4: Drivers!$B$14
Name ib_grw5: Drivers!$B$15
Name ib_hold: Drivers!$B$38
Name ib_kdLBO: Drivers!$B$37
Name ib_leverage: Drivers!$B$36
Name ib_netdebt: Drivers!$B$7
Name ib_nwcpct: Drivers!$B$19
Name ib_px: Drivers!$B$6
Name ib_rf: Drivers!$B$23
Name ib_shares: Drivers!$B$5
Name ib_spread: Drivers!$B$27
Name ib_sweep: Drivers!$B$39
Name ib_tax: Drivers!$B$20
Name ib_tg: Drivers!$B$31
Name ib_WACC: DCF!$B$13
Name ib_wd: Drivers!$B$28

Sheet Cover
A1: ⚠ DEMO DATA — see 'Data Sources' tab
A2: Market data was sourced from a synthetic test harness, NOT live yfinance. Re-run `python run_model.py MU` to refresh against live market data.
A3: Market data as-of: 2026-05-08 02:59 UTC · Source: demo/synthetic
A4: Micron Technology, Inc. (MU) — IB Valuation Template
A6: Sector / Industry | B6: Technology / Semiconductors
A7: Reporting Currency | B7: USD
A8: Fiscal Year End | B8: 2025-08-31
A9: As-of Date | B9: 2026-05-08
A10: Industry Preset | B10: semiconductors_ai_cycle
A11: Mid-cycle method | B11: peak_half
A13: Cycle phase | B13: Near peak
A14: Position in margin range | B14: 0.96403877
A15: Latest EBITDA margin | B15: 0.46478873
A16: 5y peak margin | B16: 0.48680744
A17: 5y trough margin | B17: -0.12548263
A19: Headline outputs (linked)
A20: Current Market Price | B20: 108.45
A21: DCF Implied Price | B21: =DCF!B40
A22: DCF Upside / (Downside) | B22: =B18/B17-1
A23: LBO Sponsor IRR | B23: =LBO!B40
A24: LBO Sponsor MOIC | B24: =LBO!B41
A26: Sanity check status | B26: 0 errors, 2 warnings — see Sanity Checks tab
A28: How to use this workbook
A29: 1. Yellow cells (Drivers tab) are the editable inputs — every other tab references them. 2. Edit any yellow cell to see the model recalculate live. 3. Cycle Diagnostic tab shows where the company sits in its own margin range. 4. Sanity Checks tab auto-flags issues (negative FCF, leverage breach, etc.). 5. To value a different company, open the notebook, change the TICKER cell, and Run All. 6. Notes tab logs every fallback or imputation used.

Sheet Drivers
A1: DRIVERS — every yellow cell is editable
A3: Company snapshot
A4: Ticker | B4: MU
A5: Shares Outstanding | B5: 1120000000 | C5: ⚠ DEMO fetched 2026-05-08 02:59 UTC
A6: Current Share Price | B6: 108.45 | C6: ⚠ DEMO fetched 2026-05-08 02:59 UTC
A7: Net Debt (latest) | B7: 3850000000 | C7: ⚠ DEMO fetched 2026-05-08 02:59 UTC
A8: Beta (observed equity) | B8: 1.27 | C8: ⚠ DEMO fetched 2026-05-08 02:59 UTC
A10: Operating drivers (Forecast uses these)
A11: Revenue Growth Y1 | B11: 0.35
A12: Revenue Growth Y2 | B12: 0.2
A13: Revenue Growth Y3 | B13: 0.1
A14: Revenue Growth Y4 | B14: 0.06
A15: Revenue Growth Y5 | B15: 0.04
A16: EBITDA Margin (mid-cycle) | B16: 0.46470506 | C16: 5y mid-cycle (peak_half)
A17: D&A % Revenue | B17: 0.18
A18: Capex % Revenue | B18: 0.32
A19: NWC % Δ Revenue | B19: 0.16
A20: Effective Tax Rate | B20: 0.15
A22: WACC inputs
A23: Risk-free rate | B23: 0.04
A24: Equity risk premium | B24: 0.055
A25: Asset beta (delevered) | B25: 1.1578158
A26: Re-levered β @ target | B26: 1.3738472
A27: Credit spread (bps) | B27: 175
A28: Target Debt / EV | B28: 0.18
A30: Terminal value
A31: Terminal Growth (Gordon) | B31: 0.03
A32: Exit EBITDA Multiple | B32: 10
A34: LBO assumptions
A35: Entry EBITDA Multiple | B35: 11
A36: Debt / EBITDA at close | B36: 4
A37: Cost of LBO debt | B37: 0.085
A38: Hold period (yrs) | B38: 5
A39: Cash sweep % | B39: 0.75

Sheet Data Sources
A1: DATA SOURCES & FRESHNESS — MU (Micron Technology, Inc.)
A3: Data pulled at | B3: 2026-05-08 02:59 UTC
A4: Primary source | B4: demo/synthetic
A5: Demo / synthetic mode | B5: YES — see warning on Cover
A6: Has stale/fallback data? | B6: YES
A8: PER-FIELD PROVENANCE
A9: Field | B9: Value | C9: Source | D9: Fetched at | E9: Status
A10: price | B10: 108.4500 | C10: demo/synthetic | D10: 2026-05-08 02:59 UTC | E10: demo
A11: shares_out | B11: 1,120,000,000.0000 | C11: demo/synthetic | D11: 2026-05-08 02:59 UTC | E11: demo
A12: market_cap | B12: 121,500,000,000.0000 | C12: demo/synthetic | D12: 2026-05-08 02:59 UTC | E12: demo
A13: total_debt | B13: 13,850,000,000.0000 | C13: demo/synthetic | D13: 2026-05-08 02:59 UTC | E13: demo
A14: cash | B14: 10,000,000,000.0000 | C14: demo/synthetic | D14: 2026-05-08 02:59 UTC | E14: demo
A15: enterprise_value | B15: 125,350,000,000.0000 | C15: demo/synthetic | D15: 2026-05-08 02:59 UTC | E15: demo
A16: beta | B16: 1.2700 | C16: demo/synthetic | D16: 2026-05-08 02:59 UTC | E16: demo
A17: dividend_yield | B17: 0.0042 | C17: demo/synthetic | D17: 2026-05-08 02:59 UTC | E17: demo
A19: HOW TO REFRESH AGAINST LIVE DATA
A21: From the model directory, run:
A22: python run_model.py MU
A24: yfinance pulls fresh price, shares, debt, beta, and statements.
A25: The freshly-built workbook will replace this one and the banner
A26: above will turn green ('LIVE MARKET DATA — pulled <timestamp>').
A28: If yfinance fails or fields are missing, fallbacks are still
A29: logged with status='fallback' / 'synthesized' so you can audit
A30: exactly which numbers were inferred vs. reported.

Sheet Historicals
A1: Historical Financials (sourced: yfinance)
A2: Line Item | B2: 2021-08-31 | C2: 2022-08-31 | D2: 2023-08-31 | E2: 2024-08-31 | F2: 2025-08-31
A3: Revenue | B3: 27705000000 | C3: 30758000000 | D3: 15540000000 | E3: 25111000000 | F3: 35500000000
A4: YoY Growth % | C4: 0.11019672 | D4: -0.49476559 | E4: 0.61589447 | F4: 0.41372307
A5: Gross Profit | B5: 8533000000 | C5: 11740000000 | D5: -1416000000 | E5: 5611000000 | F5: 13500000000
A6: Gross Margin % | B6: 0.30799495 | C6: 0.38168932 | D6: -0.091119691 | E6: 0.22344789 | F6: 0.38028169
A7: EBITDA | B7: 13487000000 | C7: 13611000000 | D7: -1950000000 | E7: 8700000000 | F7: 16500000000
A8: EBITDA Margin % | B8: 0.48680744 | C8: 0.44251902 | D8: -0.12548263 | E8: 0.34646171 | F8: 0.46478873
A9: EBIT | B9: 6811000000 | C9: 8911000000 | D9: -5745000000 | E9: 811000000 | F9: 8300000000
A10: EBIT Margin % | B10: 0.2458401 | C10: 0.28971325 | D10: -0.36969112 | E10: 0.032296603 | F10: 0.23380282
A11: D&A | B11: 6676000000 | C11: 4700000000 | D11: 3795000000 | E11: 7889000000 | F11: 8200000000
A12: D&A % Revenue | B12: 0.24096733 | C12: 0.15280577 | D12: 0.24420849 | E12: 0.31416511 | F12: 0.23098592
A13: Net Income | B13: 5861000000 | C13: 8687000000 | D13: -5833000000 | E13: 778000000 | F13: 7220000000
A14: Net Margin % | B14: 0.21155026 | C14: 0.28243059 | D14: -0.37535393 | E14: 0.030982438 | F14: 0.20338028
A15: Diluted EPS | B15: 5.14 | C15: 7.79 | D15: -5.34 | E15: 0.7 | F15: 6.45
A16: Capex | B16: 9704000000 | C16: 12067000000 | D16: 7676000000 | E16: 8186000000 | F16: 10500000000
... A26: Total Equity | B26: 44137000000 | C26: 47180000000 | D26: 40544000000 | E26: 41200000000 | F26: 44300000000
A27: ROE % | C27: 0.1902603 | D27: -0.13298527 | E27: 0.019035036 | F27: 0.16888889
A28: ROIC % | C28: 0.18028201 | D28: -0.11716995 | E28: 0.017498813 | F28: 0.14827883
A29: Working Capital | B29: 5575000000 | C29: 7396000000 | D29: 7340000000 | E29: 7800000000 | F29: 7700000000
A30: NWC % Revenue | B30: 0.20122722 | C30: 0.24045777 | D30: 0.47232947 | E30: 0.31062084 | F30: 0.21690141

Sheet Cycle Diagnostic
A1: Cycle Position Diagnostic
A3: Cycle phase | B3: Near peak
A4: Position in margin range | B4: 0.96403877
A5: Latest EBITDA margin | B5: 0.46478873
A6: 5y peak margin | B6: 0.48680744
A7: 5y trough margin | B7: -0.12548263
A8: 5y median margin | B8: 0.44251902
A9: 5y mean margin | B9: 0.32301885
A10: Number of obs | B10: 5
A12: Methodology used by this preset
A13: Mid-cycle method | B13: peak_half
A14: Window (years) | B14: 5
A16: How to read this
A17: Position 0% = at trough margin, 100% = at peak margin. For cyclicals, valuing off the latest reported margin is dangerous when position is >85% (near peak) or <15% (near trough). The mid-cycle method normalizes — winsorize drops outliers; peak_half assumes structural shift; median is robust to one bad year.

Sheet Forecast
A1: 5-Year Operating Forecast (formulas)
A2: Line Item | B2: FY2025 (Actual) | C2: FY2026E | D2: FY2027E | E2: FY2028E | F2: FY2029E | G2: FY2030E
A3: Revenue | B3: 35500000000 | C3: =B3*(1+ib_grw1) | D3: =C3*(1+ib_grw2) | E3: =D3*(1+ib_grw3) | F3: =E3*(1+ib_grw4) | G3: =F3*(1+ib_grw5)
A4: YoY % | C4: =ib_grw1 | D4: =ib_grw2 | E4: =ib_grw3 | F4: =ib_grw4 | G4: =ib_grw5
A5: EBITDA | C5: =C3*ib_ebmgn | D5: =D3*ib_ebmgn | E5: =E3*ib_ebmgn | F5: =F3*ib_ebmgn | G5: =G3*ib_ebmgn
A6: EBITDA Margin % | C6: =ib_ebmgn | D6: =ib_ebmgn | E6: =ib_ebmgn | F6: =ib_ebmgn | G6: =ib_ebmgn
A7: D&A | C7: =C3*ib_dapct | D7: =D3*ib_dapct | E7: =E3*ib_dapct | F7: =F3*ib_dapct | G7: =G3*ib_dapct
A8: EBIT | C8: =C5-C7 | D8: =D5-D7 | E8: =E5-E7 | F8: =F5-F7 | G8: =G5-G7
A9: Cash Taxes | C9: =C8*ib_tax | D9: =D8*ib_tax | E9: =E8*ib_tax | F9: =F8*ib_tax | G9: =G8*ib_tax
A10: NOPAT | C10: =C8-C9 | D10: =D8-D9 | E10: =E8-E9 | F10: =F8-F9 | G10: =G8-G9
A11: Capex | C11: =C3*ib_cxpct | D11: =D3*ib_cxpct | E11: =E3*ib_cxpct | F11: =F3*ib_cxpct | G11: =G3*ib_cxpct
A12: Δ NWC | C12: =(C3-B3)*ib_nwcpct | D12: =(D3-C3)*ib_nwcpct | E12: =(E3-D3)*ib_nwcpct | F12: =(F3-E3)*ib_nwcpct | G12: =(G3-F3)*ib_nwcpct
A13: Unlevered FCF | C13: =C10+C7-C11-C12 | D13: =D10+D7-D11-D12 | E13: =E10+E7-E11-E12 | F13: =F10+F7-F11-F12 | G13: =G10+G7-G11-G12

Sheet 3-Statement
A1: Three-Statement Projection
A3: Income Statement
B4: FY2026E | C4: FY2027E | D4: FY2028E | E4: FY2029E | F4: FY2030E
A5: Revenue | B5: 47925000000 | C5: 57510000000 | D5: 6.3261e+10 | E5: 6.705666e+10 | F5: 6.9738926e+10
A6: Gross Profit | B6: 8.188943e+09 | C6: 9.8267316e+09 | D6: 1.0809405e+10 | E6: 1.1457969e+10 | F6: 1.1916288e+10
A7: EBITDA | B7: 2.227099e+10 | C7: 2.6725188e+10 | D7: 2.9397707e+10 | E7: 3.1161569e+10 | F7: 3.2408032e+10
A8: D&A | B8: 8626500000 | C8: 10351800000 | D8: 11386980000 | E8: 12070198800 | F8: 12553006752
A9: EBIT | B9: 1.364449e+10 | C9: 1.6373388e+10 | D9: 1.8010727e+10 | E9: 1.9091371e+10 | F9: 1.9855025e+10
A10: Interest Expense | B10: 482500000 | C10: 482500000 | D10: 482500000 | E10: 482500000 | F10: 482500000
A11: Pretax Income | B11: 1.316199e+10 | C11: 1.5890888e+10 | D11: 1.7528227e+10 | E11: 1.8608871e+10 | F11: 1.9372525e+10
A12: Tax | B12: 1.9742985e+09 | C12: 2.3836332e+09 | D12: 2.629234e+09 | E12: 2.7913306e+09 | F12: 2.9058788e+09
A13: Net Income | B13: 1.1187692e+10 | C13: 1.3507255e+10 | D13: 1.4898993e+10 | E13: 1.581754e+10 | F13: 1.6466647e+10
A14: Diluted Shares | B14: 1120000000 | C14: 1120000000 | D14: 1120000000 | E14: 1120000000 | F14: 1120000000
A15: Diluted EPS | B15: 9.9890104 | C15: 12.060049 | D15: 13.302672 | E15: 14.122804 | F15: 14.702363
A18: Cash Flow Statement
B19: FY2026E | C19: FY2027E | D19: FY2028E | E19: FY2029E | F19: FY2030E
A20: Net Income | B20: 1.1187692e+10 | C20: 1.3507255e+10 | D20: 1.4898993e+10 | E20: 1.581754e+10 | F20: 1.6466647e+10
A21: + D&A | B21: 8626500000 | C21: 10351800000 | D21: 11386980000 | E21: 12070198800 | F21: 12553006752
A22: − Δ NWC | B22: -1988000000 | C22: -1533600000 | D22: -9.2016e+08 | E22: -6.073056e+08 | F22: -429162624
A23: Operating Cash Flow | B23: 1.7826192e+10 | C23: 2.2325455e+10 | D23: 2.5365813e+10 | E23: 2.7280433e+10 | F23: 2.8590491e+10
A24: − Capex | B24: -15336000000 | C24: -18403200000 | D24: -20243520000 | E24: -21458131200 | F24: -22316456448
A25: Free Cash Flow | B25: 2.4901916e+09 | C25: 3.9222549e+09 | D25: 5.1222929e+09 | E25: 5.822302e+09 | F25: 6.2740343e+09
A26: − Mandatory Debt Amort | B26: 0 | C26: 0 | D26: 0 | E26: 0 | F26: 0
A27: − Dividends | B27: 0 | C27: 0 | D27: 0 | E27: 0 | F27: 0
A28: =Net Change in Cash | B28: 2.4901916e+09 | C28: 3.9222549e+09 | D28: 5.1222929e+09 | E28: 5.822302e+09 | F28: 6.2740343e+09
A29: Beginning Cash | B29: 8400000000 | C29: 1.0890192e+10 | D29: 1.4812447e+10 | E29: 1.9934739e+10 | F29: 2.5757041e+10
A30: Ending Cash | B30: 1.0890192e+10 | C30: 1.4812447e+10 | D30: 1.9934739e+10 | E30: 2.5757041e+10 | F30: 3.2031076e+10
A33: Balance Sheet
B34: FY2026E | C34: FY2027E | D34: FY2028E | E34: FY2029E | F34: FY2030E
A35: Cash & Equivalents | B35: 1.0890192e+10 | C35: 1.4812447e+10 | D35: 1.9934739e+10 | E35: 2.5757041e+10 | F35: 3.2031076e+10
A36: Receivables | B36: 7.425e+09 | C36: 8910000000 | D36: 9801000000 | E36: 10389060000 | F36: 10804622400
A37: Inventory | B37: 10260000000 | C37: 12312000000 | D37: 13543200000 | E37: 14355792000 | F37: 14930023680
A38: Net PPE | B38: 52709500000 | C38: 60760900000 | D38: 69617440000 | E38: 79005372400 | F38: 88768822096
A39: Other Assets | B39: 5500000000 | C39: 5500000000 | D39: 5500000000 | E39: 5500000000 | F39: 5500000000
A40: Total Assets | B40: 8.6784692e+10 | C40: 1.0229535e+11 | D40: 1.1839638e+11 | E40: 1.3500727e+11 | F40: 1.5203454e+11
A41: Payables | B41: 7290000000 | C41: 8748000000 | D41: 9622800000 | E41: 10200168000 | F41: 10608174720
A42: Total Debt | B42: 13850000000 | C42: 13850000000 | D42: 13850000000 | E42: 13850000000 | F42: 13850000000
A43: Other Liabilities | B43: 10157000000 | C43: 10702400000 | D43: 11029640000 | E43: 11245618400 | F43: 11398243136
A44: Total Liabilities | B44: 31297000000 | C44: 33300400000 | D44: 34502440000 | E44: 35295786400 | F44: 35856417856
A45: Retained Earnings (delta) | B45: 1.1187692e+10 | C45: 2.4694947e+10 | D45: 3.9593939e+10 | E45: 5.5411479e+10 | F45: 7.1878126e+10
...

Sheet DCF
A1: DCF Valuation (formulas)
A3: WACC Build (with Hamada re-levering)
A4: Risk-free rate | B4: =ib_rf
A5: ERP | B5: =ib_erp
A6: Re-levered β | B6: =ib_betaT
A7: Cost of Equity | B7: =B4+B5*B6
A8: Pre-tax kd | B8: =B4+ib_spread/10000
A9: Tax | B9: =ib_tax
A10: After-tax kd | B10: =B8*(1-B9)
A11: Wd | B11: =ib_wd
A12: We | B12: =1-B11
A13: WACC | B13: =B7*B12+B10*B11
A15: Year | B15: 1 | C15: 2 | D15: 3 | E15: 4 | F15: 5
A16: FCF | B16: =Forecast!C13 | C16: =Forecast!D13 | D16: =Forecast!E13 | E16: =Forecast!F13 | F16: =Forecast!G13
A17: Discount Factor (mid-yr) | B17: =1/(1+ib_WACC)^(1-0.5) | C17: =1/(1+ib_WACC)^(2-0.5) | D17: =1/(1+ib_WACC)^(3-0.5) | E17: =1/(1+ib_WACC)^(4-0.5) | F17: =1/(1+ib_WACC)^(5-0.5)
A18: PV of FCF | B18: =B16*B17 | C18: =C16*C17 | D18: =D16*D17 | E18: =E16*E17 | F18: =F16*F17
A20: Sum PV explicit | B20: =SUM(B18:F18)
A21: Y5 FCF | B21: =F16
A22: TV — Gordon | B22: =B21*(1+ib_tg)/(ib_WACC-ib_tg)
A23: TV — Exit Mult | B23: =ib_EBDA5*ib_exitm
A24: TV — Blended | B24: =AVERAGE(B22,B23)
A25: PV of TV | B25: =B24*F17
A26: Enterprise Value | B26: =B20+B25
A27: Less: Net Debt | B27: =ib_netdebt
A28: Equity Value | B28: =B26-B27
A29: Diluted Shares | B29: =ib_shares
A30: Implied Price | B30: =B28/B29
A31: Current Price | B31: =ib_px
A32: Upside % | B32: =B30/B31-1
A33: TV % of EV | B33: =B25/B26
A40: Headline DCF Px | B40: =B30

Sheet LBO
A1: LBO Model — Sources/Uses, Debt Schedule, Returns
A3: Sources
A4: Source | B4: $ Amount | C4: % Total
A5: New Term Debt | B5: =ib_EBDA1*ib_leverage | C5: =B5/B7
A6: Sponsor Equity | B6: =B12-B5+B11 | C6: =B6/B7
A7: Total Sources | B7: =B5+B6 | C7: =1
A9: Uses
A10: Use | B10: $ Amount
A11: Transaction Fees (2% EV) | B11: =B12*0.02
A12: Equity Purchase Price | B12: =ib_EBDA1*ib_entrym
A13: Total Uses | B13: =B11+B12
A15: Debt schedule (formulas)
A16: Year | B16: Y1 | C16: Y2 | D16: Y3 | E16: Y4 | F16: Y5
A17: Beginning Debt | B17: =B5 | C17: =B26 | D17: =C26 | E17: =D26 | F17: =E26
A18: Mandatory Amort (1%) | B18: =B17*0.01 | C18: =C17*0.01 | D18: =D17*0.01 | E18: =E17*0.01 | F18: =F17*0.01
A19: Cash Interest | B19: =B17*ib_kdLBO | C19: =C17*ib_kdLBO | D19: =D17*ib_kdLBO | E19: =E17*ib_kdLBO | F19: =F17*ib_kdLBO
A20: EBITDA | B20: =Forecast!C5 | C20: =Forecast!D5 | D20: =Forecast!E5 | E20: =Forecast!F5 | F20: =Forecast!G5
A21: Less: Cash Taxes | B21: =(Forecast!C8-B19)*ib_tax | C21: =(Forecast!D8-C19)*ib_tax | D21: =(Forecast!E8-D19)*ib_tax | E21: =(Forecast!F8-E19)*ib_tax | F21: =(Forecast!G8-F19)*ib_tax
A22: Less: Capex | B22: =Forecast!C11 | C22: =Forecast!D11 | D22: =Forecast!E11 | E22: =Forecast!F11 | F22: =Forecast!G11
A23: Less: Δ NWC | B23: =Forecast!C12 | C23: =Forecast!D12 | D23: =Forecast!E12 | E23: =Forecast!F12 | F23: =Forecast!G12
A24: CFADS | B24: =B20-B19-MAX(0,B21)-B22-B23 | C24: =C20-C19-MAX(0,C21)-C22-C23 | D24: =D20-D19-MAX(0,D21)-D22-D23 | E24: =E20-E19-MAX(0,E21)-E22-E23 | F24: =F20-F19-MAX(0,F21)-F22-F23
A25: Cash Sweep | B25: =MIN(MAX(0,(B24-B18))*ib_sweep,MAX(0,B17-B18)) | C25: =MIN(MAX(0,(C24-C18))*ib_sweep,MAX(0,C17-C18)) | D25: =MIN(MAX(0,(D24-D18))*ib_sweep,MAX(0,D17-D18)) | E25: =MIN(MAX(0,(E24-E18))*ib_sweep,MAX(0,E17-E18)) | F25: =MIN(MAX(0,(F24-F18))*ib_sweep,MAX(0,F17-F18))
A26: Ending Debt | B26: =B17-B18-B25 | C26: =C17-C18-C25 | D26: =D17-D18-D25 | E26: =E17-E18-E25 | F26: =F17-F18-F25
A27: Net Debt / EBITDA | B27: =B26/B20 | C27: =C26/C20 | D27: =D26/D20 | E27: =E26/E20 | F27: =F26/F20
A28: Interest Coverage | B28: =B20/B19 | C28: =C20/C19 | D28: =D20/D19 | E28: =E20/E19 | F28: =F20/F19
A30: Sponsor Returns
A31: Exit Year EBITDA | B31: =Forecast!G5
A32: Exit Multiple | B32: =ib_exitm
A33: Exit EV | B33: =B31*B32
A34: Less: Exit Debt | B34: =F26
A35: Plus: Retained Cash | B35: =SUMPRODUCT((B24:F24-B25:F25-B18:F18>0)*(B24:F24-B25:F25-B18:F18))
A36: Equity to Sponsor | B36: =B33-B34+B35
A37: Sponsor Equity Invested | B37: =B6
A38: MOIC | B38: =B36/B37
A39: Hold Period | B39: =ib_hold
A40: IRR | B40: =B38^(1/B39)-1
A41: MOIC (linked) | B41: =B38

Sheet Returns Attribution
A1: LBO Returns Attribution
A3: Decomposition of value created over hold
A4: Driver | B4: $ Contribution | C4: % of Total | D4: Notes
A5: EBITDA Growth | B5: 1.1150746e+11 | C5: 1.3359718 | D5: =(Exit EBITDA − Entry EBITDA) × Entry Multiple
A6: Multiple Expansion / (Compression) | B6: -3.2408032e+10 | C6: -0.3882809 | D6: =Exit EBITDA × (Exit Mult − Entry Mult)
A7: Debt Paydown + Cash Generation | B7: 4.3660005e+09 | C7: 0.052309087 | D7: =ΔDebt + retained cash + recaps
A8: Total Value Creation | B8: 8.3465431e+10 | C8: 1 | D8: Sum of above (≈ change in sponsor equity)
A11: How to read this
A12: If EBITDA Growth dominates, the deal works on operational improvement. If Multiple Expansion dominates, the thesis is multiple re-rating — fragile. If Debt Paydown dominates, the deal is a financial-engineering bet — sensitive to interest rate environment and refinancing risk.

Sheet M&A
A1: M&A Accretion / Dilution
A3: Transaction summary
A4: Target Current Price | B4: 65
A5: Premium % | B5: 0.3
A6: Offer Price/Share | B6: 84.5
A7: Target Shares Outstanding | B7: 2.3076923e+08
A8: Equity Purchase Price | B8: 19500000000
A9: Target Net Debt Assumed | B9: 3050000000
A10: Deal Fees | B10: 338250000
A11: Total Deal Value | B11: 22550000000
A14: Pro-forma EPS by financing mix
A15: Metric | B15: All Stock | C15: All Cash | D15: 50/50 Mix
A16: Stock % | B16: 1 | C16: 0 | D16: 0.5
A17: Cash % | B17: 0 | C17: 1 | D17: 0.5
A18: New Shares Issued | B18: 1.7980636e+08 | C18: 0 | D18: 89903181
A19: New Debt Raised | B19: 338250000 | C19: 19838250000 | D19: 10088250000
A20: After-tax Interest | B20: 20125875 | C20: 1180375875 | D20: 6.0025088e+08
A21: Synergies (after-tax) | B21: 564187500 | C21: 564187500 | D21: 564187500
A22: Pro-forma Net Income | B22: 8164061625 | C22: 7003811625 | D22: 7583936625
A23: Pro-forma Shares | B23: 1.2998064e+09 | C23: 1120000000 | D23: 1.2099032e+09
A24: Pro-forma EPS | B24: 6.280983 | C24: 6.2534032 | D24: 6.2682178
A25: Acquirer Standalone EPS | B25: 6.4464286 | C25: 6.4464286 | D25: 6.4464286
A26: Accretion / (Dilution) % | B26: -0.025664692 | C26: -0.029942988 | D26: -0.027644888

Sheet Comps
A1: Comparable Company Analysis
A3: Ticker | B3: Name | C3: Sector | D3: Industry | E3: Price | F3: Market Cap | G3: Enterprise Value | H3: Revenue (LTM) | I3: EBITDA (LTM, Adj) | J3: Net Income (LTM) | K3: Diluted EPS (LTM) | L3: Forward EPS | M3: Book Value | N3: EV/Revenue (LTM) | O3: EV/EBITDA (LTM) | P3: EV/EBITDA (yf) | Q3: P/E (LTM) | R3: Forward P/E | S3: P/B
A4: MU | B4: Micron Technology, Inc. | C4: Technology | D4: Semiconductors | E4: 108.45 | F4: 121500000000 | G4: 125350000000 | H4: 35500000000 | I4: 15910000000 | J4: 7220000000 | K4: 6.45 | M4: 44300000000 | N4: 3.5309859 | O4: 7.8786926 | Q4: 16.813953 | R4: 14.2 | S4: 2.7426637
A5: WDC | B5: Western Digital | C5: Technology | D5: Semiconductors | E5: 65 | F5: 15000000000 | G5: 19000000000 | H5: 12500000000 | I5: 1250000000 | J5: 400000000 | K5: 1.2 | M5: 5000000000 | N5: 1.52 | O5: 15.2 | Q5: 54.166667 | S5: 3
A6: STX | B6: Seagate Technology | C6: Technology | D6: Semiconductors | E6: 102 | F6: 22000000000 | G6: 27000000000 | H6: 7000000000 | I6: 1260000000 | J6: 600000000 | K6: 2.85 | M6: 1500000000 | N6: 3.8571429 | O6: 21.428571 | Q6: 35.789474 | S6: 14.666667
A7: NVDA | B7: NVIDIA | C7: Technology | D7: Semiconductors | E7: 122 | F7: 3000000000000 | G7: 2980000000000 | H7: 130000000000 | I7: 77400000000 | J7: 60000000000 | K7: 2.45 | M7: 50000000000 | N7: 22.923077 | O7: 38.501292 | Q7: 49.795918 | S7: 60
A8: TSM | B8: Taiwan Semiconductor | C8: Technology | D8: Semiconductors | E8: 175 | F8: 900000000000 | G8: 870000000000 | H8: 90000000000 | I8: 58200000000 | J8: 33000000000 | K8: 6.3 | M8: 110000000000 | N8: 9.6666667 | O8: 14.948454 | Q8: 27.777778 | S8: 8.1818182
A9: AVGO | B9: Broadcom | C9: Technology | D9: Semiconductors | E9: 168 | F9: 790000000000 | G9: 850000000000 | H9: 50000000000 | I9: 29000000000 | J9: 14000000000 | K9: 3.1 | M9: 70000000000 | N9: 17 | O9: 29.310345 | Q9: 54.193548 | S9: 11.285714
A10: INTC | B10: Intel | C10: Technology | D10: Semiconductors | E10: 23 | F10: 100000000000 | G10: 130000000000 | H10: 55000000000 | I10: 8900000000 | J10: 1000000000 | K10: 0.2 | M10: 110000000000 | N10: 2.3636364 | O10: 14.606742 | Q10: 115 | S10: 0.90909091
A11: AMD | B11: AMD | C11: Technology | D11: Semiconductors | E11: 137 | F11: 220000000000 | G11: 230000000000 | H11: 25000000000 | I11: 4500000000 | J11: 2000000000 | K11: 1.2 | M11: 55000000000 | N11: 9.2 | O11: 51.111111 | Q11: 114.16667 | S11: 4
A13: Peer-set statistics
A14: Multiple | B14: Min | C14: p25 | D14: Median | E14: Mean | F14: p75 | G14: Max | H14: Std
A15: EV/Revenue (LTM) | B15: 1.52 | C15: 3.1103896 | D15: 9.2 | E15: 9.5043604 | F15: 13.333333 | G15: 22.923077 | H15: 7.9895407
A16: EV/EBITDA (LTM) | B16: 14.606742 | C16: 15.074227 | D16: 21.428571 | E16: 26.443788 | F16: 33.905818 | G16: 51.111111 | H16: 14.05887
A17: EV/EBITDA (yf) | B17: 0 | C17: 0 | D17: 0 | E17: 0 | F17: 0 | G17: 0 | H17: 0
A18: P/E (LTM) | B18: 27.777778 | C18: 42.792696 | D18: 54.166667 | E18: 64.412865 | F18: 84.180108 | G18: 115 | H18: 35.634724
A19: Forward P/E | B19: 0 | C19: 0 | D19: 0 | E19: 0 | F19: 0 | G19: 0 | H19: 0
A20: P/B | B20: 0.90909091 | C20: 3.5 | D20: 8.1818182 | E20: 14.577613 | F20: 12.97619 | G20: 60 | H20: 20.606227
A22: Implied valuation w/ p25-p75 bands
A23: Multiple | B23: Multiple | C23: p25 mult | D23: Median mult | E23: p75 mult | F23: Low $/sh | G23: High $/sh | H23: Median $/sh
A24: EV/Revenue (LTM) | B24: 3.1103896 | C24: 9.2 | D24: 13.333333 | E24: 95.150742 | F24: 419.18155 | G24: 257.16614
A25: EV/EBITDA (LTM) | B25: 15.074227 | C25: 21.428571 | D25: 33.905818 | E25: 210.69728 | F25: 478.20676 | G25: 344.45202
A26: Forward P/E
A27: P/E (LTM) | B27: 42.792696 | C27: 54.166667 | D27: 84.180108 | E27: 276.01289 | F27: 542.96169 | G27: 409.48729
A28: P/B | B28: 3.5 | C28: 8.1818182 | D28: 12.97619 | E28: 135 | F28: 509.81718 | G28: 322.40859

Sheet Sensitivity
A1: Sensitivity Tables
A3: DCF — Implied Price (WACC × Terminal Growth)
A4: WACC \ Terminal g | B4: 2.50% | C4: 2.75% | D4: 3.00% | E4: 3.25% | F4: 3.50%
A5: 9.36% | B5: 121.65644 | C5: 122.86094 | D5: 124.1602 | E5: 125.56586 | F5: 127.09154
A6: 9.86% | B6: 117.27214 | C6: 118.29925 | D6: 119.40126 | E6: 120.58669 | F6: 121.86537
A7: 10.36% | B7: 113.27416 | C7: 114.1585 | D7: 115.10295 | E7: 116.11386 | F7: 117.1985
A8: 10.86% | B8: 109.59929 | C8: 110.36718 | D8: 111.18395 | E8: 112.05441 | F8: 112.98404
A9: 11.36% | B9: 106.19839 | C9: 106.87017 | D9: 107.58214 | E9: 108.33804 | F9: 109.14204
A12: LBO — Sponsor IRR (Entry × Exit)
A13: Entry × Exit | B13: 9.0x | C13: 9.5x | D13: 10.0x | E13: 10.5x | F13: 11.0x
A14: 10.0x | B14: 0.090447837 | C14: 0.10701274 | D14: 0.12264169 | E14: 0.13744586 | F14: 0.15151718
A15: 10.5x | B15: 0.072876128 | C15: 0.0891741 | D15: 0.1045512 | E15: 0.11911682 | F15: 0.13296138
A16: 11.0x | B16: 0.056877249 | C16: 0.072932184 | D16: 0.088079976 | E16: 0.10242839 | F16: 0.11606651
A17: 11.5x | B17: 0.042210938 | C17: 0.058043077 | D17: 0.072980664 | E17: 0.087129966 | F17: 0.10057882
A18: 12.0x | B18: 0.028686863 | C18: 0.04431356 | D18: 0.059057311 | E18: 0.073023007 | F18: 0.086297348
A21: M&A — Y1 Accretion (Premium × Cost-Synergy)
A22: Premium \ Cost Synergy % | B22: 3.0% | C22: 4.0% | D22: 5.0% | E22: 6.0% | F22: 7.0%
A23: 20% | B23: -0.032633959 | C23: -0.023828866 | D23: -0.015023773 | E23: -0.0062186801 | F23: 0.0025864128
A24: 25% | B24: -0.037888681 | C24: -0.029130686 | D24: -0.020372691 | E24: -0.011614697 | F24: -0.0028567019
A25: 30% | B25: -0.043087487 | C25: -0.03437609 | D25: -0.025664692 | E25: -0.016953294 | F25: -0.0082418963
A26: 35% | B26: -0.048231266 | C26: -0.039565972 | D26: -0.030900678 | E26: -0.022235384 | F26: -0.01357009
A27: 40% | B27: -0.053320886 | C27: -0.04470121 | D27: -0.036081535 | E27: -0.027461859 | F27: -0.018842183

Sheet Football
A1: Football Field — Implied Equity Value Range
A3: Method | B3: Low | C3: Mid | D3: High | E3: vs Current | F3: Source
A5: 52-Week Trading Range | B5: 56.343612 | C5: 92.115251 | D5: 127.88689 | E5: -0.15062009 | F5: Trading history (last 252 days)
A6: DCF (WACC ±100bps) | B6: 125.41524 | C6: 133.67485 | D6: 143.50865 | E6: 0.23259426 | F6: WACC sensitivity: 9.4% → 11.4%
A7: Comps EV/EBITDA (p25 / median / p75) | B7: 210.69728 | C7: 344.45202 | D7: 478.20676 | E7: 2.1761366 | F7: Peer median × subject EBITDA, p25/p75 bands
A8: Comps P/E (p25 / median / p75) | B8: 276.01289 | C8: 409.48729 | D8: 542.96169 | E8: 2.7758164 | F8: Peer median × subject EPS
A9: LBO (sponsor IRR 25% → 15%) | B9: 146.56969 | C9: 162.11601 | D9: 182.08365 | E9: 0.49484561 | F9: Implied take-private price at sponsor IRR brackets
A11: Current price | B11: =ib_px

Sheet Reverse-DCF
A1: Reverse-DCF — what does today's price require? (MU)
A3: Headline implied assumptions
A4: Current Enterprise Value | B4: 125350000000
A5: Current Share Price | B5: 108.45
A7: Implied perpetual growth rate | B7: -0.05
A8: Preset growth assumption | B8: 0.03
A9: Spread vs preset (bps) | B9: -800
A11: Implied EBITDA margin (g held at preset) | B11: 0.42390551
A13: Interpretation
A14: Market implies NEGATIVE long-term growth — i.e., the company shrinks in perpetuity. Either market is wrong or the cash-flow profile is structurally challenged.
A17: Joint sensitivity grid: EV implied / Current EV
A18: Each cell = model EV at (margin, growth) ÷ current EV. Cells near 1.0 = where the market sits. Far above = model says cheap; far below = model says expensive.
A20: EBITDA Margin \ Terminal g | B20: -1.0% | C20: 0.0% | D20: 1.5% | E20: 2.5% | F20: 3.5% | G20: 4.5%
A21: 20% | B21: -0.11345649 | C21: -0.13509581 | D21: -0.176718 | E21: -0.21329658 | F21: -0.260546 | G21: -0.32393307
A22: 30% | B22: 0.35805733 | C22: 0.35065949 | D22: 0.33643011 | E22: 0.32392499 | F22: 0.30777182 | G22: 0.28610167
A23: 35% | B23: 0.59381425 | C23: 0.59353715 | D23: 0.59300417 | E23: 0.59253577 | F23: 0.59193073 | G23: 0.59111904
A24: 40% | B24: 0.82957116 | C24: 0.8364148 | D24: 0.84957822 | E24: 0.86114655 | F24: 0.87608964 | G24: 0.89613641
A25: 45% | B25: 1.0653281 | C25: 1.0792925 | D25: 1.1061523 | E25: 1.1297573 | F25: 1.1602486 | G25: 1.2011538
A26: 50% | B26: 1.301085 | C26: 1.3221701 | D26: 1.3627263 | E26: 1.3983681 | F26: 1.4444075 | G26: 1.5061712

Sheet Reverse-LBO
A1: Reverse-LBO — max entry multiple at target sponsor IRR (MU)
A3: Take-private price ceiling by IRR target
A4: Solves bisection for the highest entry multiple at which the sponsor still hits target IRR, given preset exit and leverage. Premium > 0 means the deal still works at a premium to current market.
A6: Target IRR | B6: Max Entry Multiple | C6: Implied $/Share | D6: Premium to Market | E6: Read
A7: 15% | B7: 9.329791 | C7: 182.08365 | D7: 0.67896401 | E7: PE could pay +68% premium
A8: 20% | B8: 8.3256257 | C8: 162.11601 | D8: 0.49484561 | E8: PE could pay +49% premium
A9: 25% | B9: 7.5438073 | C9: 146.56969 | D9: 0.35149557 | E9: PE could pay +35% premium
A10: 30% | B10: 6.9289648 | C10: 134.34367 | D10: 0.23876133 | E10: PE could pay +24% premium
A13: How to use
A14: Compare Implied $/Share at 20% IRR (PE base case) vs current market. If take-private > current → public market is paying LESS than a sponsor would. If take-private < current → public is paying MORE; sponsor wouldn't bid. Useful framework even outside actual buyout situations — tells you where 'patient capital' would step in.

Sheet Sanity Checks
A1: Sanity Checks — auto-flagged issues
A3: Level | B3: Area | C3: Message
A5: WARN | B5: DCF | C5: Terminal value = 87% of EV (target <80%). DCF is essentially a perpetuity — explicit forecast doing little work.
A6: WARN | B6: LBO | C6: Sponsor IRR 8.8% < typical 20%+ PE target. Either entry too rich, exit too low, or hold too short.
A7: INFO | B7: Data | C7: 20 fallback / imputation note(s) — see Notes tab.

Sheet Notes
A1: Audit Trail
A2: Every fallback or imputation used by the model is logged below.
A4: [02:59:25] ⚠ DEMO MODE: data sourced from synthetic test harness, NOT live yfinance.
A5: [02:59:26] EBITDA margin set via peak_half of trailing 5y (values: [48.7, 44.3, -12.5, 34.6, 46.5]) → 46.5%.
A6: [02:59:26] ⚠ Terminal value = 87% of EV (target <80%). Consider longer explicit forecast or lower terminal growth.
A7: [02:59:26] ⚠ Terminal value = 86% of EV (target <80%). Consider longer explicit forecast or lower terminal growth.
A8: [02:59:26] ⚠ Terminal value = 86% of EV (target <80%). Consider longer explicit forecast or lower terminal growth.
A9: [02:59:26] ⚠ Terminal value = 86% of EV (target <80%). Consider longer explicit forecast or lower terminal growth.
A10: [02:59:26] ⚠ Terminal value = 86% of EV (target <80%). Consider longer explicit forecast or lower terminal growth.
A11: [02:59:26] ⚠ Terminal value = 86% of EV (target <80%). Consider longer explicit forecast or lower terminal growth.
A12: [02:59:26] ⚠ Terminal value = 85% of EV (target <80%). Consider longer explicit forecast or lower terminal growth.
A13: [02:59:26] ⚠ Terminal value = 86% of EV (target <80%). Consider longer explicit forecast or lower terminal growth.
... A25: [02:59:26] ⚠ Terminal value = 88% of EV (target <80%). Consider longer explicit forecast or lower terminal growth.
